<?xml version='1.0'?>
<robot name="robot">
  <!-- Base Link -->
  <link name="base_link">
    <visual>
      <origin xyz="0 0 0.125" rpy="0 0 0" />
      <geometry>
        <box size="0.35 0.24 0.15" />
      </geometry>
      <material name="white" >
        <color rgba="1 1 1 1" />
      </material>
    </visual>
    <collision>
      <origin xyz="0 0 0.125" rpy="0 0 0" />
      <geometry>
        <box size="0.35 0.24 0.15" />
      </geometry>
    </collision>
    <inertial>
      <mass value="5" />
      <inertia ixx="0.13" ixy="0.0" ixz="0.0"
               iyy="0.21" iyz="0.0" izz="0.13" />
    </inertial>

    <!-- Caster -->
    <visual>
      <origin xyz="0.13 0 0.0175" rpy="0 0 0" />
      <geometry>
        <sphere radius="0.0175" />
      </geometry>
      <material name="black" >
        <color rgba="0.05 0.05 0.05 1" />
      </material>
    </visual>
    <collision>
      <origin xyz="0.13 0 -0.02" rpy="0 0 0" />
      <geometry>
        <sphere radius="0.0175" />
      </geometry>
    </collision>
    <inertial>
      <mass value="0.5" />
      <inertia ixx="0.0001" ixy="0.0" ixz="0.0"
               iyy="0.0001" iyz="0.0" izz="0.0001" />
    </inertial>

    <visual>
      <origin xyz="-0.13 0 0.0175" rpy="0 0 0" />
      <geometry>
        <sphere radius="0.0175" />
      </geometry>
      <material name="black" />
    </visual>
    <collision>
      <origin xyz="-0.13 0 -0.02" rpy="0 0 0" />
      <geometry>
        <sphere radius="0.0175" />
      </geometry>
    </collision>
    <inertial>
      <mass value="0.5" />
      <inertia ixx="0.0001" ixy="0.0" ixz="0.0"
               iyy="0.0001" iyz="0.0" izz="0.0001" />
    </inertial>
  </link>

  <!-- Right wheel -->
  <link name="right_wheel">
    <visual>
      <origin xyz="0 0 0" rpy="1.570795 0 0" />
      <geometry>
        <cylinder length="0.03" radius="0.035" />
      </geometry>
      <material name="black" />
    </visual>
    <collision>
      <origin xyz="0 0 0" rpy="1.570795 0 0" />
      <geometry>
        <cylinder length="0.03" radius="0.035" />
      </geometry>
    </collision>
    <inertial>
      <mass value="0.5" />
      <inertia ixx="0.01" ixy="0.0" ixz="0.0"
               iyy="0.005" iyz="0.0" izz="0.005" />
    </inertial>
  </link>
  <joint name="joint_right_wheel" type="continuous">
    <parent link="base_link" />
    <child link="right_wheel" />
    <origin xyz="0 -0.135 0.035" rpy="0 0 0" />
    <axis xyz="0 1 0" />
  </joint>

  <!-- Left wheel -->
  <link name="left_wheel">
    <visual>
      <origin xyz="0 0 0" rpy="1.570795 0 0" />
      <geometry>
        <cylinder length="0.03" radius="0.035" />
      </geometry>
      <material name="black" />
    </visual>
    <collision>
      <origin xyz="0 0 0" rpy="1.570795 0 0" />
      <geometry>
        <cylinder length="0.03" radius="0.035" />
      </geometry>
    </collision>
    <inertial>
      <mass value="0.5" />
      <inertia ixx="0.01" ixy="0.0" ixz="0.0"
               iyy="0.005" iyz="0.0" izz="0.005" />
    </inertial>
  </link>
  <joint name="joint_left_wheel" type="continuous">
    <parent link="base_link" />
    <child link="left_wheel" />
    <origin xyz="0 0.135 0.035" rpy="0 0 0" />
    <axis xyz="0 1 0" />
  </joint>
</robot>
